<mujoco model="C:\Users\aleks\Desktop\Aleksie kerefeke\master\RS projekat - RL politika ucenja joystick\mujoco-bipedal-joystick-walker\generated_models\human_male_180cm_75kg_base">
  <compiler angle="radian"/>

  <option timestep="0.005" integrator="implicitfast" iterations="4" ls_iterations="5"/>

  <size nkey="2"/>

  <visual>
    <global azimuth="120" elevation="-20" offwidth="2560" offheight="1440"/>
    <map force="0.1" zfar="30"/>
    <rgba haze="0.15 0.25 0.35 1"/>
  </visual>

  <statistic extent="2.2" center="0 0 0.9"/>

  <asset>
    <texture type="2d" colorspace="auto" name="groundplane" builtin="checker" rgb1="1 1 1" rgb2="0.85 0.85 0.85" width="300" height="300"/>
    <material name="groundplane" texture="groundplane" texuniform="true" texrepeat="6 6"/>
  </asset>

  <worldbody>
    <geom name="floor" size="0 0 0.01" type="plane" conaffinity="0" friction="0.8" material="groundplane"/>
    <light pos="0 0 3" dir="0 0 -1" diffuse="0.8 0.8 0.8"/>
    <body name="thorax" pos="0 0 1.51881" quat="0.707107 0.707107 0 0">
      <inertial pos="0 -0.188512 -0.00135864" quat="0.718249 0.690455 -0.0591617 -0.062367" mass="22.8" diaginertia="0.469541 0.340997 0.280826"/>
      <joint type="free"/>
      <geom size="0.0849153 0.169831 0.153051" pos="0 -0.169831 0" type="box" contype="0" conaffinity="0" rgba="0.2 0.4 0.8 1"/>
      <site name="seventh_cervicale" pos="-0.0732203 0.0264407 0" size="0.02" rgba="1 0 0 1"/>
      <site name="suprasternale" pos="0.0518644 -0.039661 0" size="0.02" rgba="1 0 0 1"/>
      <site name="acromion_right" pos="-0.0274576 -0.0457627 0.209492" size="0.02" rgba="1 0 0 1"/>
      <site name="acromion_left" pos="-0.0274576 -0.0457627 -0.209492" size="0.02" rgba="1 0 0 1"/>
      <site name="shoulder_joint_centre_right" pos="0.019322 -0.0844068 0.209492" size="0.02" rgba="1 0 0 1"/>
      <site name="shoulder_joint_centre_left" pos="0.019322 -0.0844068 -0.209492" size="0.02" rgba="1 0 0 1"/>
      <site name="thoracic_joint_centre" pos="0 -0.339661 0" size="0.02" rgba="1 0 0 1"/>
      <site name="centre_of_mass_thorax" pos="0 -0.188136 0.00101695" size="0.02" rgba="1 0 0 1"/>
      <body name="head">
        <inertial pos="0.00565424 0.150968 0.000282712" quat="0.526977 0.447232 -0.539459 0.480898" mass="5.025" diaginertia="0.0361625 0.0317533 0.0174302"/>
        <joint name="head_x" pos="0 0 0" axis="1 0 0" stiffness="12" range="-0.785398 0.785398" armature="0.003" damping="2" frictionloss="0.3"/>
        <joint name="head_y" pos="0 0 0" axis="0 1 0" stiffness="12" range="-1.39626 1.39626" armature="0.003" damping="2" frictionloss="0.3"/>
        <joint name="head_z" pos="0 0 0" axis="0 0 1" stiffness="12" range="-1.0472 1.309" armature="0.003" damping="2" frictionloss="0.3"/>
        <geom size="0.141356" pos="0 0.141356 0" contype="0" conaffinity="0" rgba="0.2 0.4 0.8 1"/>
        <site name="head_vertex" pos="0 0.281695 0" size="0.02" rgba="1 0 0 1"/>
        <site name="sellion" pos="0.10678 0.175932 0" size="0.02" rgba="1 0 0 1"/>
        <site name="occiput" pos="-0.0742373 0.101695 0" size="0.02" rgba="1 0 0 1"/>
        <site name="centre_of_mass_head" pos="-0.00610169 0.151525 0" size="0.02" rgba="1 0 0 1"/>
      </body>
      <body name="abdomen" pos="0 -0.339661 0">
        <inertial pos="0.0270264 -0.0554349 -0.00506746" quat="0.735971 0.00609623 0.0124617 0.67687" mass="2.175" diaginertia="0.0223941 0.0149081 0.00820008"/>
        <joint name="abdomen_x" pos="0 0 0" axis="1 0 0" stiffness="5000" limited="true" range="-1.74533e-05 1.74533e-05" armature="0.05" damping="80" frictionloss="10"/>
        <joint name="abdomen_y" pos="0 0 0" axis="0 1 0" stiffness="5000" limited="true" range="-1.74533e-05 1.74533e-05" armature="0.05" damping="80" frictionloss="10"/>
        <joint name="abdomen_z" pos="0 0 0" axis="0 0 1" stiffness="5000" limited="true" range="-1.74533e-05 1.74533e-05" armature="0.05" damping="80" frictionloss="10"/>
        <geom size="0.0767797 0.101949" pos="0 -0.0767797 0" type="capsule" contype="0" conaffinity="0" rgba="0.2 0.4 0.8 1"/>
        <site name="midspine_at_tenth_rib_level" pos="-0.0589831 -0.0254237 0" size="0.02" rgba="1 0 0 1"/>
        <site name="tenth_rib_right" pos="0.0335593 -0.0315254 0.149492" size="0.02" rgba="1 0 0 1"/>
        <site name="tenth_rib_left" pos="0.0335593 -0.0315254 -0.149492" size="0.02" rgba="1 0 0 1"/>
        <site name="iliocristale_right" pos="0.020339 -0.0813559 0.159661" size="0.02" rgba="1 0 0 1"/>
        <site name="iliocristale_left" pos="0.020339 -0.0813559 -0.159661" size="0.02" rgba="1 0 0 1"/>
        <site name="anterior_superior_iliac_spine_right" pos="0.0701695 -0.182034 0.113898" size="0.02" rgba="1 0 0 1"/>
        <site name="anterior_superior_iliac_spine_left" pos="0.0701695 -0.182034 -0.113898" size="0.02" rgba="1 0 0 1"/>
        <site name="lumbar_joint_centre" pos="0 -0.153559 0" size="0.02" rgba="1 0 0 1"/>
        <site name="centre_of_mass_abdomen" pos="0.0264407 -0.0559322 0" size="0.02" rgba="1 0 0 1"/>
        <body name="pelvis" pos="0 -0.153559 0">
          <inertial pos="-0.000189153 -0.0266705 -0.000567458" quat="0.511311 0.0473642 0.0743465 0.854862" mass="10.65" diaginertia="0.110225 0.096187 0.0875248"/>
          <joint name="pelvis_x" pos="0 0 0" axis="1 0 0" stiffness="5000" limited="true" range="-1.74533e-05 1.74533e-05" armature="0.05" damping="80" frictionloss="10"/>
          <joint name="pelvis_y" pos="0 0 0" axis="0 1 0" stiffness="5000" limited="true" range="-1.74533e-05 1.74533e-05" armature="0.05" damping="80" frictionloss="10"/>
          <joint name="pelvis_z" pos="0 0 0" axis="0 0 1" stiffness="5000" limited="true" range="-1.74533e-05 1.74533e-05" armature="0.05" damping="80" frictionloss="10"/>
          <geom size="0.0472881 0.119237" pos="0 -0.0472881 0" type="capsule" contype="0" conaffinity="0" rgba="0.2 0.4 0.8 1"/>
          <site name="midpoint_between_postero_superior_iliac_spines" pos="-0.103729 0.00711864 0" size="0.02" rgba="1 0 0 1"/>
          <site name="antero_superior_iliac_spine_right" pos="0.079322 0.00711864 0.113898" size="0.02" rgba="1 0 0 1"/>
          <site name="antero_superior_iliac_spine_left" pos="0.079322 0.00711864 -0.113898" size="0.02" rgba="1 0 0 1"/>
          <site name="symphision" pos="0.125085 -0.0681356 0" size="0.02" rgba="1 0 0 1"/>
          <site name="hip_joint_centre_right" pos="0.0569492 -0.0762712 0.0823729" size="0.02" rgba="1 0 0 1"/>
          <site name="hip_joint_centre_left" pos="0.0569492 -0.0762712 -0.0823729" size="0.02" rgba="1 0 0 1"/>
          <site name="centre_of_mass_pelvis" pos="-0.00305085 -0.0264407 0" size="0.02" rgba="1 0 0 1"/>
          <body name="left_thigh" pos="0 -0.0945763 -0.101012">
            <inertial pos="-0.0180122 -0.188469 -0.0144976" quat="0.530849 0.529475 -0.429159 0.503665" mass="9.225" diaginertia="0.161039 0.150243 0.038756"/>
            <joint name="left_hip_x" pos="0 0 0" axis="1 0 0" range="-0.349066 0.698132" armature="0.01" damping="4" frictionloss="0.3"/>
            <joint name="left_hip_y" pos="0 0 0" axis="0 1 0" range="-0.698132 0.872665" armature="0.01" damping="4" frictionloss="0.3"/>
            <joint name="left_hip_z" pos="0 0 0" axis="0 0 1" range="-0.523599 1.74533" armature="0.01" damping="4" frictionloss="0.3"/>
            <geom size="0.0828814 0.17822" pos="0 -0.219661 0" quat="0.707107 -0.707107 0 0" type="capsule" contype="0" conaffinity="0" rgba="0.2 0.4 0.8 1"/>
            <site name="greater_trochanter_left" pos="-0.040678 0.00610169 -0.102712" size="0.02" rgba="1 0 0 1"/>
            <site name="lateral_femoral_epicondyle_left" pos="0 -0.438305 -0.0579661" size="0.02" rgba="1 0 0 1"/>
            <site name="medial_femoral_epicondyle_left" pos="0 -0.439322 0.0579661" size="0.02" rgba="1 0 0 1"/>
            <site name="centre_of_mass_thigh_left" pos="-0.0183051 -0.188136 -0.0142373" size="0.02" rgba="1 0 0 1"/>
            <body name="left_shank" pos="0 -0.439322 0">
              <inertial pos="-0.0211363 -0.180539 -0.00308237" quat="0.64875 0.657637 -0.281288 0.259834" mass="3.6" diaginertia="0.055057 0.0544467 0.00692845"/>
              <joint name="left_knee_z" pos="0 0 0" axis="0 0 1" range="-2.61799 0" armature="0.01" damping="5" frictionloss="0.8"/>
              <geom size="0.0523729 0.193983" pos="0 -0.220169 0" quat="0.707107 -0.707107 0 0" type="capsule" contype="0" conaffinity="0" rgba="0.2 0.4 0.8 1"/>
              <site name="tibiale_head_left" pos="0.0213559 -0.0274576 0.0427119" size="0.02" rgba="1 0 0 1"/>
              <site name="fibula_head_left" pos="0 -0.0233898 -0.0477966" size="0.02" rgba="1 0 0 1"/>
              <site name="sphyrion_left" pos="0.0213559 -0.441356 0.0335593" size="0.02" rgba="1 0 0 1"/>
              <site name="lateral_malleolus_left" pos="-0.0213559 -0.440339 -0.0335593" size="0.02" rgba="1 0 0 1"/>
              <site name="centre_of_mass_shank_left" pos="-0.0213559 -0.181017 -0.00305085" size="0.02" rgba="1 0 0 1"/>
              <body name="left_foot" pos="0 -0.440339 0">
                <inertial pos="0.0709607 -0.0281298 -0.0048061" quat="0.487468 0.581843 0.43977 0.480038" mass="0.9" diaginertia="0.00439861 0.00415298 0.000779968"/>
                <joint name="left_ankle_y" pos="0 0 0" axis="0 1 0" range="-0.523599 0.523599" armature="0.01" damping="10" frictionloss="1"/>
                <joint name="left_ankle_z" pos="0 0 0" axis="0 0 1" range="-0.349066 0.523599" armature="0.01" damping="10" frictionloss="1"/>
                <geom size="0.0513559 0.045" pos="0.070678 0 0" quat="0.707107 0 0.707107 0" type="capsule" contype="0" conaffinity="0" solimp="0.85 0.95 0.005" rgba="0.2 0.4 0.8 1"/>
                <geom name="left_foot_sole" size="0.145 0.012 0.075" pos="0.09 -0.045 0" type="box" friction="1 0.01 0.001" solimp="0.85 0.95 0.005" rgba="0.1 0.1 0.1 0.35"/>
                <site name="calcaneous_left" pos="-0.0467797 -0.0213559 -0.00711864" size="0.02" rgba="1 0 0 1"/>
                <site name="first_metatarsal_head_left" pos="0.148475 -0.0213559 0.0477966" size="0.02" rgba="1 0 0 1"/>
                <site name="fifth_metatarsal_head_left" pos="0.130169 -0.0213559 -0.0610169" size="0.02" rgba="1 0 0 1"/>
                <site name="second_toe_tip_left" pos="0.222712 -0.00915254 0.00101695" size="0.02" rgba="1 0 0 1"/>
                <site name="centre_of_mass_foot_left" pos="0.0457627 -0.0366102 -0.00610169" size="0.02" rgba="1 0 0 1"/>
                <site name="metatarsal_midpoint_left" pos="0.105763 0 0" size="0.02" rgba="1 0 0 1"/>
              </body>
            </body>
          </body>
          <body name="right_thigh" pos="0 -0.0945763 0.101012">
            <inertial pos="-0.0180122 -0.188469 0.0144976" quat="0.429159 0.503665 -0.530849 0.529475" mass="9.225" diaginertia="0.161039 0.150243 0.038756"/>
            <joint name="right_hip_x" pos="0 0 0" axis="1 0 0" range="-0.698132 0.349066" armature="0.01" damping="4" frictionloss="0.3"/>
            <joint name="right_hip_y" pos="0 0 0" axis="0 1 0" range="-0.698132 0.872665" armature="0.01" damping="4" frictionloss="0.3"/>
            <joint name="right_hip_z" pos="0 0 0" axis="0 0 1" range="-0.523599 1.74533" armature="0.01" damping="4" frictionloss="0.3"/>
            <geom size="0.0828814 0.17822" pos="0 -0.219661 0" quat="0.707107 -0.707107 0 0" type="capsule" contype="0" conaffinity="0" rgba="0.2 0.4 0.8 1"/>
            <site name="greater_trochanter_right" pos="-0.040678 0.00610169 0.102712" size="0.02" rgba="1 0 0 1"/>
            <site name="lateral_femoral_epicondyle_right" pos="0 -0.438305 0.0579661" size="0.02" rgba="1 0 0 1"/>
            <site name="medial_femoral_epicondyle_right" pos="0 -0.439322 -0.0579661" size="0.02" rgba="1 0 0 1"/>
            <site name="centre_of_mass_thigh_right" pos="-0.0183051 -0.188136 0.0142373" size="0.02" rgba="1 0 0 1"/>
            <body name="right_shank" pos="0 -0.439322 0">
              <inertial pos="-0.0211363 -0.180539 0.00308237" quat="0.281288 0.259834 -0.64875 0.657637" mass="3.6" diaginertia="0.055057 0.0544467 0.00692845"/>
              <joint name="right_knee_z" pos="0 0 0" axis="0 0 1" range="-2.61799 0" armature="0.01" damping="5" frictionloss="0.8"/>
              <geom size="0.0523729 0.193983" pos="0 -0.220169 0" quat="0.707107 -0.707107 0 0" type="capsule" contype="0" conaffinity="0" rgba="0.2 0.4 0.8 1"/>
              <site name="tibiale_head_right" pos="0.0213559 -0.0274576 -0.0427119" size="0.02" rgba="1 0 0 1"/>
              <site name="fibula_head_right" pos="0 -0.0233898 0.0477966" size="0.02" rgba="1 0 0 1"/>
              <site name="sphyrion_right" pos="0.0213559 -0.441356 -0.0335593" size="0.02" rgba="1 0 0 1"/>
              <site name="lateral_malleolus_right" pos="-0.0213559 -0.440339 0.0335593" size="0.02" rgba="1 0 0 1"/>
              <site name="centre_of_mass_shank_right" pos="-0.0213559 -0.181017 0.00305085" size="0.02" rgba="1 0 0 1"/>
              <body name="right_foot" pos="0 -0.440339 0">
                <inertial pos="0.0709607 -0.0281298 0.0048061" quat="0.581843 0.487468 0.480038 0.43977" mass="0.9" diaginertia="0.00439861 0.00415298 0.000779968"/>
                <joint name="right_ankle_y" pos="0 0 0" axis="0 1 0" range="-0.523599 0.523599" armature="0.01" damping="10" frictionloss="1"/>
                <joint name="right_ankle_z" pos="0 0 0" axis="0 0 1" range="-0.349066 0.523599" armature="0.01" damping="10" frictionloss="1"/>
                <geom size="0.0513559 0.045" pos="0.070678 0 0" quat="0.707107 0 0.707107 0" type="capsule" contype="0" conaffinity="0" solimp="0.85 0.95 0.005" rgba="0.2 0.4 0.8 1"/>
                <geom name="right_foot_sole" size="0.145 0.012 0.075" pos="0.09 -0.045 0" type="box" friction="1 0.01 0.001" solimp="0.85 0.95 0.005" rgba="0.1 0.1 0.1 0.35"/>
                <site name="calcaneous_right" pos="-0.0467797 -0.0213559 0.00711864" size="0.02" rgba="1 0 0 1"/>
                <site name="first_metatarsal_head_right" pos="0.148475 -0.0213559 -0.0477966" size="0.02" rgba="1 0 0 1"/>
                <site name="fifth_metatarsal_head_right" pos="0.130169 -0.0213559 0.0610169" size="0.02" rgba="1 0 0 1"/>
                <site name="second_toe_tip_right" pos="0.222712 -0.00915254 -0.00101695" size="0.02" rgba="1 0 0 1"/>
                <site name="centre_of_mass_foot_right" pos="0.0457627 -0.0366102 0.00610169" size="0.02" rgba="1 0 0 1"/>
                <site name="metatarsal_midpoint_right" pos="0.105763 0 0" size="0.02" rgba="1 0 0 1"/>
              </body>
            </body>
          </body>
        </body>
      </body>
      <body name="left_upper_arm" pos="0.019322 -0.0844068 -0.209492">
        <inertial pos="0.00507051 -0.135777 0.00873254" quat="0.532725 0.445317 -0.440748 0.568892" mass="1.8" diaginertia="0.0133878 0.0120245 0.00186887"/>
        <joint name="left_shoulder_x" pos="0 0 0" axis="1 0 0" stiffness="25" range="-0.872665 3.14159" armature="0.006" damping="3" frictionloss="0.8"/>
        <joint name="left_shoulder_y" pos="0 0 0" axis="0 1 0" stiffness="25" range="-1.5708 1.5708" armature="0.006" damping="3" frictionloss="0.8"/>
        <joint name="left_shoulder_z" pos="0 0 0" axis="0 0 1" stiffness="25" range="-0.872665 3.14159" armature="0.006" damping="3" frictionloss="0.8"/>
        <geom size="0.0513559 0.115169" pos="0 -0.115169 0" quat="0.707107 -0.707107 0 0" type="capsule" contype="0" conaffinity="0" rgba="0.2 0.4 0.8 1"/>
        <site name="lateral_humeral_epicondyle_left" pos="0 -0.262373 -0.0416949" size="0.02" rgba="1 0 0 1"/>
        <site name="medial_humeral_epicondyle_left" pos="0 -0.268475 0.0416949" size="0.02" rgba="1 0 0 1"/>
        <site name="centre_of_mass_upper_arm_left" pos="0.00508475 -0.12 -0.00711864" size="0.02" rgba="1 0 0 1"/>
        <body name="left_forearm" pos="0 -0.281695 0">
          <inertial pos="-0.00374136 -0.120011 -0.00316576" quat="0.701607 0.709256 -0.00145823 0.068567" mass="1.275" diaginertia="0.00834467 0.00827899 0.0012129"/>
          <joint name="left_elbow_z" pos="0 0 0" axis="0 0 1" stiffness="12" range="0 2.61799" armature="0.006" damping="2" frictionloss="0.5"/>
          <geom size="0.0437288 0.122034" pos="0 -0.143898 0" quat="0.707107 -0.707107 0 0" type="capsule" contype="0" conaffinity="0" rgba="0.2 0.4 0.8 1"/>
          <site name="olecranion_left" pos="-0.00813559 0.0142373 0.0223729" size="0.02" rgba="1 0 0 1"/>
          <site name="ulnar_styloid_left" pos="0 -0.288814 0.0335593" size="0.02" rgba="1 0 0 1"/>
          <site name="radial_styloid_left" pos="0 -0.288814 -0.0335593" size="0.02" rgba="1 0 0 1"/>
          <site name="centre_of_mass_forearm_left" pos="0.00305085 -0.12 -0.0040678" size="0.02" rgba="1 0 0 1"/>
          <body name="left_hand" pos="0 -0.287797 0">
            <inertial pos="0.00667119 -0.0682576 -0.00610169" quat="0.782886 0.607421 0.134599 -0.00346203" mass="0.45" diaginertia="0.00114688 0.000954987 0.00037055"/>
            <joint name="left_wrist_y" pos="0 0 0" axis="0 1 0" stiffness="6" range="-1.39626 1.39626" armature="0.003" damping="2" frictionloss="0.3"/>
            <joint name="left_wrist_z" pos="0 0 0" axis="0 0 1" stiffness="6" range="-1.0472 1.0472" armature="0.003" damping="2" frictionloss="0.3"/>
            <geom size="0.0452542 0.0180508" pos="0 -0.040678 0" quat="0.707107 -0.707107 0 0" type="capsule" contype="0" conaffinity="0" rgba="0.2 0.4 0.8 1"/>
            <site name="secnd_metacarpal_head_left" pos="0 -0.0874576 -0.0467797" size="0.02" rgba="1 0 0 1"/>
            <site name="fifth_metacarpal_head_left" pos="0 -0.0762712 0.0467797" size="0.02" rgba="1 0 0 1"/>
            <site name="third_finger_tip_left" pos="0.00711864 -0.192203 0.00101695" size="0.02" rgba="1 0 0 1"/>
            <site name="centre_of_mass_left" pos="0.00711864 -0.0691525 -0.00610169" size="0.02" rgba="1 0 0 1"/>
          </body>
        </body>
      </body>
      <body name="right_upper_arm" pos="0.019322 -0.0844068 0.209492">
        <inertial pos="0.00507051 -0.135777 -0.00873254" quat="0.440748 0.568892 -0.532725 0.445317" mass="1.8" diaginertia="0.0133878 0.0120245 0.00186887"/>
        <joint name="right_shoulder_x" pos="0 0 0" axis="1 0 0" stiffness="25" range="-3.14159 0.872665" armature="0.006" damping="3" frictionloss="0.8"/>
        <joint name="right_shoulder_y" pos="0 0 0" axis="0 1 0" stiffness="25" range="-1.5708 1.5708" armature="0.006" damping="3" frictionloss="0.8"/>
        <joint name="right_shoulder_z" pos="0 0 0" axis="0 0 1" stiffness="25" range="-0.872665 3.14159" armature="0.006" damping="3" frictionloss="0.8"/>
        <geom size="0.0513559 0.115169" pos="0 -0.115169 0" quat="0.707107 -0.707107 0 0" type="capsule" contype="0" conaffinity="0" rgba="0.2 0.4 0.8 1"/>
        <site name="lateral_humeral_epicondyle_right" pos="0 -0.262373 0.0416949" size="0.02" rgba="1 0 0 1"/>
        <site name="medial_humeral_epicondyle_right" pos="0 -0.268475 -0.0416949" size="0.02" rgba="1 0 0 1"/>
        <site name="centre_of_mass_upper_arm_right" pos="0.00508475 -0.12 0.00711864" size="0.02" rgba="1 0 0 1"/>
        <body name="right_forearm" pos="0 -0.281695 0">
          <inertial pos="-0.00374136 -0.120011 0.00316576" quat="0.709256 0.701607 0.068567 -0.00145823" mass="1.275" diaginertia="0.00834467 0.00827899 0.0012129"/>
          <joint name="right_elbow_z" pos="0 0 0" axis="0 0 1" stiffness="12" range="0 2.61799" armature="0.006" damping="2" frictionloss="0.5"/>
          <geom size="0.0437288 0.122034" pos="0 -0.143898 0" quat="0.707107 -0.707107 0 0" type="capsule" contype="0" conaffinity="0" rgba="0.2 0.4 0.8 1"/>
          <site name="olecranion_right" pos="-0.00813559 0.0142373 -0.0223729" size="0.02" rgba="1 0 0 1"/>
          <site name="ulnar_styloid_right" pos="0 -0.288814 -0.0335593" size="0.02" rgba="1 0 0 1"/>
          <site name="radial_styloid_right" pos="0 -0.288814 0.0335593" size="0.02" rgba="1 0 0 1"/>
          <site name="centre_of_mass_forearm_right" pos="0.00305085 -0.12 0.0040678" size="0.02" rgba="1 0 0 1"/>
          <body name="right_hand" pos="0 -0.287797 0">
            <inertial pos="0.00667119 -0.0682576 0.00610169" quat="0.607421 0.782886 -0.00346203 0.134599" mass="0.45" diaginertia="0.00114688 0.000954987 0.00037055"/>
            <joint name="right_wrist_y" pos="0 0 0" axis="0 1 0" stiffness="6" range="-1.39626 1.39626" armature="0.003" damping="2" frictionloss="0.3"/>
            <joint name="right_wrist_z" pos="0 0 0" axis="0 0 1" stiffness="6" range="-1.0472 1.0472" armature="0.003" damping="2" frictionloss="0.3"/>
            <geom size="0.0452542 0.0180508" pos="0 -0.040678 0" quat="0.707107 -0.707107 0 0" type="capsule" contype="0" conaffinity="0" rgba="0.2 0.4 0.8 1"/>
            <site name="secnd_metacarpal_head_right" pos="0 -0.0874576 0.0467797" size="0.02" rgba="1 0 0 1"/>
            <site name="fifth_metacarpal_head_right" pos="0 -0.0762712 -0.0467797" size="0.02" rgba="1 0 0 1"/>
            <site name="third_finger_tip_right" pos="0.00711864 -0.192203 -0.00101695" size="0.02" rgba="1 0 0 1"/>
            <site name="centre_of_mass_right" pos="0.00711864 -0.0691525 0.00610169" size="0.02" rgba="1 0 0 1"/>
          </body>
        </body>
      </body>
    </body>
  </worldbody>

  <contact>
    <exclude body1="thorax" body2="head"/>
    <exclude body1="thorax" body2="abdomen"/>
    <exclude body1="thorax" body2="left_upper_arm"/>
    <exclude body1="thorax" body2="right_upper_arm"/>
    <exclude body1="abdomen" body2="pelvis"/>
    <exclude body1="pelvis" body2="left_thigh"/>
    <exclude body1="pelvis" body2="right_thigh"/>
    <exclude body1="left_thigh" body2="left_shank"/>
    <exclude body1="left_shank" body2="left_foot"/>
    <exclude body1="right_thigh" body2="right_shank"/>
    <exclude body1="right_shank" body2="right_foot"/>
    <exclude body1="left_upper_arm" body2="left_forearm"/>
    <exclude body1="left_forearm" body2="left_hand"/>
    <exclude body1="right_upper_arm" body2="right_forearm"/>
    <exclude body1="right_forearm" body2="right_hand"/>
  </contact>

  <equality>
    <joint name="lock_abdomen_x" joint1="abdomen_x" polycoef="0 1 0 0 0" solref="0.002" solimp="0.999 0.9999 0.0001"/>
    <joint name="lock_abdomen_y" joint1="abdomen_y" polycoef="0 1 0 0 0" solref="0.002" solimp="0.999 0.9999 0.0001"/>
    <joint name="lock_abdomen_z" joint1="abdomen_z" polycoef="0 1 0 0 0" solref="0.002" solimp="0.999 0.9999 0.0001"/>
    <joint name="lock_pelvis_x" joint1="pelvis_x" polycoef="0 1 0 0 0" solref="0.002" solimp="0.999 0.9999 0.0001"/>
    <joint name="lock_pelvis_y" joint1="pelvis_y" polycoef="0 1 0 0 0" solref="0.002" solimp="0.999 0.9999 0.0001"/>
    <joint name="lock_pelvis_z" joint1="pelvis_z" polycoef="0 1 0 0 0" solref="0.002" solimp="0.999 0.9999 0.0001"/>
  </equality>

  <actuator>
    <general name="left_hip_x_position" joint="left_hip_x" ctrllimited="true" ctrlrange="-0.349066 0.698132" forcelimited="true" forcerange="-180 180" biastype="affine" gainprm="100" biasprm="0 -100"/>
    <general name="left_hip_y_position" joint="left_hip_y" ctrllimited="true" ctrlrange="-0.698132 0.872665" forcelimited="true" forcerange="-180 180" biastype="affine" gainprm="100" biasprm="0 -100"/>
    <general name="left_hip_z_position" joint="left_hip_z" ctrllimited="true" ctrlrange="-0.523599 1.74533" forcelimited="true" forcerange="-180 180" biastype="affine" gainprm="100" biasprm="0 -100"/>
    <general name="left_knee_z_position" joint="left_knee_z" ctrllimited="true" ctrlrange="-2.61799 0" forcelimited="true" forcerange="-180 180" biastype="affine" gainprm="120" biasprm="0 -120"/>
    <general name="left_ankle_y_position" joint="left_ankle_y" ctrllimited="true" ctrlrange="-0.523599 0.523599" forcelimited="true" forcerange="-220 220" biastype="affine" gainprm="120" biasprm="0 -120"/>
    <general name="left_ankle_z_position" joint="left_ankle_z" ctrllimited="true" ctrlrange="-0.349066 0.523599" forcelimited="true" forcerange="-220 220" biastype="affine" gainprm="120" biasprm="0 -120"/>
    <general name="right_hip_x_position" joint="right_hip_x" ctrllimited="true" ctrlrange="-0.698132 0.349066" forcelimited="true" forcerange="-180 180" biastype="affine" gainprm="100" biasprm="0 -100"/>
    <general name="right_hip_y_position" joint="right_hip_y" ctrllimited="true" ctrlrange="-0.698132 0.872665" forcelimited="true" forcerange="-180 180" biastype="affine" gainprm="100" biasprm="0 -100"/>
    <general name="right_hip_z_position" joint="right_hip_z" ctrllimited="true" ctrlrange="-0.523599 1.74533" forcelimited="true" forcerange="-180 180" biastype="affine" gainprm="100" biasprm="0 -100"/>
    <general name="right_knee_z_position" joint="right_knee_z" ctrllimited="true" ctrlrange="-2.61799 0" forcelimited="true" forcerange="-180 180" biastype="affine" gainprm="120" biasprm="0 -120"/>
    <general name="right_ankle_y_position" joint="right_ankle_y" ctrllimited="true" ctrlrange="-0.523599 0.523599" forcelimited="true" forcerange="-220 220" biastype="affine" gainprm="120" biasprm="0 -120"/>
    <general name="right_ankle_z_position" joint="right_ankle_z" ctrllimited="true" ctrlrange="-0.349066 0.523599" forcelimited="true" forcerange="-220 220" biastype="affine" gainprm="120" biasprm="0 -120"/>
  </actuator>

  <keyframe>
    <key name="t-pose" qpos="0 0 1.51881 0.707107 0.707107 0 0 0 0 0 0 0 0 0 0 0 0 0 0 0 0 0 0 0 0 0 0 0 1.5708 0 0 0 0 0 -1.5708 0 0 0 0 0"/>
    <key name="a-pose" qpos="0 0 1.51881 0.707107 0.707107 0 0 0 0 0 0 0 0 0 0 0 0 0 0 0 0 0 0 0 0 0 0 0 0.75 0 0 0 0 0 -0.75 0 0 0 0 0"/>
  </keyframe>
</mujoco>
