<?xml version='1.0' encoding='utf-8'?>
<mujoco model="C:\Users\aleks\Desktop\Aleksie kerefeke\master\RS projekat - RL politika ucenja joystick\mujoco-bipedal-joystick-walker\generated_models\human_male_180cm_75kg_base">
  <compiler angle="degree" inertiafromgeom="false" />
  <visual>
    <map force="0.1" zfar="30" />
    <rgba haze="0.15 0.25 0.35 1" />
    <global offwidth="2560" offheight="1440" elevation="-20" azimuth="120" />
  </visual>
  <contact>
    <exclude body1="thorax" body2="head" />
    <exclude body1="thorax" body2="abdomen" />
    <exclude body1="abdomen" body2="pelvis" />
    <exclude body1="pelvis" body2="left_thigh" />
    <exclude body1="pelvis" body2="right_thigh" />
    <exclude body1="left_thigh" body2="left_shank" />
    <exclude body1="right_thigh" body2="right_shank" />
    <exclude body1="left_shank" body2="left_foot" />
    <exclude body1="right_shank" body2="right_foot" />
    <exclude body1="thorax" body2="left_upper_arm" />
    <exclude body1="thorax" body2="right_upper_arm" />
    <exclude body1="left_upper_arm" body2="left_forearm" />
    <exclude body1="right_upper_arm" body2="right_forearm" />
    <exclude body1="left_forearm" body2="left_hand" />
    <exclude body1="right_forearm" body2="right_hand" />
  </contact>
  <worldbody>
    <light diffuse=".8 .8 .8" pos="0 0 3" dir="0 0 -1" />
    <body name="thorax" pos="0 0 1.5188135593220338" euler="90 0 0">
      <joint type="free" pos="0 0 0" />
      <geom type="box" size="0.08491525423728814 0.16983050847457629 0.15305084745762712" pos="0 -0.16983050847457629 0" euler="0 0 0" rgba="0.2 0.4 0.8 1.0" contype="0" conaffinity="0" />
      <inertial mass="22.8" pos="0.0 -0.1885118644067797 -0.0013586440677966103" fullinertia="0.4640073275127837 0.28645350320942264 0.34090334266245337 -0.031828167023269176 0.00026304270267164614 0.002367384324044815" />
      <body name="head" pos="0 0 0">
        <joint name="head_x" type="hinge" axis="1 0 0" pos="0 0 0" range="-45.0 45.0" damping="2.0" armature="0.003" frictionloss="0.3" stiffness="12.0" springref="0" />
        <joint name="head_y" type="hinge" axis="0 1 0" pos="0 0 0" range="-80 80" damping="2.0" armature="0.003" frictionloss="0.3" stiffness="12.0" springref="0" />
        <joint name="head_z" type="hinge" axis="0 0 1" pos="0 0 0" range="-60 75.0" damping="2.0" armature="0.003" frictionloss="0.3" stiffness="12.0" springref="0" />
        <geom type="sphere" size="0.14135593220338985" pos="0 0.14135593220338985 0" euler="0 0 0" rgba="0.2 0.4 0.8 1.0" contype="0" conaffinity="0" />
        <inertial mass="5.025" pos="0.005654237288135594 0.15096813559322037 0.0002827118644067797" fullinertia="0.03148764628095377 0.01771180103303649 0.036146532720482634 -0.0019679778925596105 -0.0001606512565354784 0.0003614653272048263" />
        <site name="head_vertex" pos="0.0 0.2816949152542373 0.0" size="0.02" rgba="1 0 0 1" />
        <site name="sellion" pos="0.10677966101694915 0.17593220338983048 0.0" size="0.02" rgba="1 0 0 1" />
        <site name="occiput" pos="-0.07423728813559322 0.1016949152542373 0.0" size="0.02" rgba="1 0 0 1" />
        <site name="centre_of_mass_head" pos="-0.006101694915254237 0.15152542372881356 0.0" size="0.02" rgba="1 0 0 1" />
      </body>
      <body name="abdomen" pos="0 -0.33966101694915257 0">
        <joint name="abdomen_x" type="hinge" axis="1 0 0" pos="0 0 0" range="-0.001 0.001" limited="true" damping="80.0" armature="0.05" frictionloss="10.0" stiffness="5000.0" springref="0" />
        <joint name="abdomen_y" type="hinge" axis="0 1 0" pos="0 0 0" range="-0.001 0.001" limited="true" damping="80.0" armature="0.05" frictionloss="10.0" stiffness="5000.0" springref="0" />
        <joint name="abdomen_z" type="hinge" axis="0 0 1" pos="0 0 0" range="-0.001 0.001" limited="true" damping="80.0" armature="0.05" frictionloss="10.0" stiffness="5000.0" springref="0" />
        <geom type="capsule" size="0.07677966101694915 0.10194915254237288" pos="0 -0.07677966101694915 0" euler="0 0 0" rgba="0.2 0.4 0.8 1.0" contype="0" conaffinity="0" />
        <inertial mass="2.175" pos="0.027026440677966102 -0.055434915254237285 -0.005067457627118644" fullinertia="0.014955438560183852 0.022340840318299336 0.00820600195346165 0.000620578897730537 -0.00018463504395288706 -0.00012821878052283827" />
        <body name="pelvis" pos="0 -0.1535593220338983 0">
          <joint name="pelvis_x" type="hinge" axis="1 0 0" pos="0 0 0" range="-0.001 0.001" limited="true" damping="80.0" armature="0.05" frictionloss="10.0" stiffness="5000.0" springref="0" />
          <joint name="pelvis_y" type="hinge" axis="0 1 0" pos="0 0 0" range="-0.001 0.001" limited="true" damping="80.0" armature="0.05" frictionloss="10.0" stiffness="5000.0" springref="0" />
          <joint name="pelvis_z" type="hinge" axis="0 0 1" pos="0 0 0" range="-0.001 0.001" limited="true" damping="80.0" armature="0.05" frictionloss="10.0" stiffness="5000.0" springref="0" />
          <geom type="capsule" size="0.047288135593220336 0.11923728813559321" pos="0 -0.047288135593220336 0" euler="0 0 0" rgba="0.2 0.4 0.8 1.0" contype="0" conaffinity="0" />
          <inertial mass="10.649999999999999" pos="-0.00018915254237288136 -0.026670508474576266 -0.0005674576271186441" fullinertia="0.09910928108704392 0.10703497523010629 0.08779230435392127 -0.005953796681987933 -0.0013717547555300198 -0.0006096687802355644" />
          <body name="left_thigh" pos="0 -0.0945763 -0.161012">
            <joint name="left_hip_x" type="hinge" axis="1 0 0" pos="0 0 0" range="-20.0 40.0" damping="4.0" armature="0.01" frictionloss="0.3" />
            <joint name="left_hip_y" type="hinge" axis="0 1 0" pos="0 0 0" range="-40 50" damping="4.0" armature="0.01" frictionloss="0.3" />
            <joint name="left_hip_z" type="hinge" axis="0 0 1" pos="0 0 0" range="-30 100.0" damping="4.0" armature="0.01" frictionloss="0.3" />
            <geom type="capsule" size="0.08288135593220339 0.17822033898305084" pos="0 -0.21966101694915252 0" euler="-90 0 0" rgba="0.2 0.4 0.8 1.0" contype="0" conaffinity="0" />
            <inertial mass="9.225000000000001" pos="-0.018012203389830506 -0.18846915254237287 -0.014497627118644068" fullinertia="0.1497367290043091 0.040060361505314564 0.16024144602125825 0.00872425650560184 0.0007121842045389257 0.00872425650560184" />
            <body name="left_shank" pos="0 -0.43932203389830504 0">
              <joint name="left_knee_z" type="hinge" axis="0 0 1" pos="0 0 0" range="-150 0.0" damping="5.0" armature="0.01" frictionloss="0.8" />
              <geom type="capsule" size="0.052372881355932197 0.19398305084745762" pos="0 -0.22016949152542373 0" euler="-90 0 0" rgba="0.2 0.4 0.8 1.0" contype="0" conaffinity="0" />
              <inertial mass="3.6" pos="-0.021136271186440677 -0.18053898305084745 -0.0030823728813559317" fullinertia="0.054725890059178404 0.006980343119793164 0.054725890059178404 -0.001116854899166906 0.0002792137247917265 -0.001116854899166906" />
              <body name="left_foot" pos="0 -0.44033898305084745 0">
                <joint name="left_ankle_y" type="hinge" axis="0 1 0" pos="0 0 0" range="-30 30" damping="8.0" armature="0.01" frictionloss="1.0" />
                <joint name="left_ankle_z" type="hinge" axis="0 0 1" pos="0 0 0" range="-20 30.0" damping="8.0" armature="0.01" frictionloss="1.0" />
                <geom type="capsule" size="0.05135593220338983 0.04500000000000001" pos="0.07067796610169493 0 0" euler="0 90 0" rgba="0.2 0.4 0.8 1.0" solref="0.02 1" solimp="0.85 0.95 0.005" contype="0" conaffinity="0" condim="3" />
                <inertial mass="0.9" pos="0.0709606779661017 -0.028129830508474576 -0.004806101694915256" fullinertia="0.000870394121229532 0.004317802241884517 0.004143363750646367 0.000519718803792014 0.000217598530307383 -0.0" />
                <site name="calcaneous_left" pos="-0.04677966101694915 -0.02135593220338983 -0.00711864406779661" size="0.02" rgba="1 0 0 1" />
                <site name="first_metatarsal_head_left" pos="0.14847457627118643 -0.02135593220338983 0.04779661016949152" size="0.02" rgba="1 0 0 1" />
                <site name="fifth_metatarsal_head_left" pos="0.13016949152542373 -0.02135593220338983 -0.06101694915254237" size="0.02" rgba="1 0 0 1" />
                <site name="second_toe_tip_left" pos="0.22271186440677965 -0.009152542372881356 0.001016949152542373" size="0.02" rgba="1 0 0 1" />
                <site name="centre_of_mass_foot_left" pos="0.04576271186440677 -0.03661016949152542 -0.006101694915254237" size="0.02" rgba="1 0 0 1" />
                <site name="metatarsal_midpoint_left" pos="0.10576271186440676 0.0 0.0" size="0.02" rgba="1 0 0 1" />
                <geom name="left_foot_sole" type="box" pos="0.09 -0.045 0" size="0.145 0.012 0.075" rgba="0.1 0.1 0.1 0.35" friction="1.0 0.01 0.001" solref="0.02 1" solimp="0.85 0.95 0.005" contype="1" conaffinity="1" condim="3" />
              </body>
              <site name="tibiale_head_left" pos="0.02135593220338983 -0.027457627118644065 0.04271186440677966" size="0.02" rgba="1 0 0 1" />
              <site name="fibula_head_left" pos="0.0 -0.023389830508474575 -0.04779661016949152" size="0.02" rgba="1 0 0 1" />
              <site name="sphyrion_left" pos="0.02135593220338983 -0.4413559322033898 0.0335593220338983" size="0.02" rgba="1 0 0 1" />
              <site name="lateral_malleolus_left" pos="-0.02135593220338983 -0.44033898305084745 -0.0335593220338983" size="0.02" rgba="1 0 0 1" />
              <site name="centre_of_mass_shank_left" pos="-0.02135593220338983 -0.18101694915254235 -0.0030508474576271187" size="0.02" rgba="1 0 0 1" />
            </body>
            <site name="greater_trochanter_left" pos="-0.04067796610169491 0.006101694915254237 -0.10271186440677967" size="0.02" rgba="1 0 0 1" />
            <site name="lateral_femoral_epicondyle_left" pos="0.0 -0.4383050847457627 -0.057966101694915256" size="0.02" rgba="1 0 0 1" />
            <site name="medial_femoral_epicondyle_left" pos="0.0 -0.43932203389830504 0.057966101694915256" size="0.02" rgba="1 0 0 1" />
            <site name="centre_of_mass_thigh_left" pos="-0.01830508474576271 -0.18813559322033896 -0.01423728813559322" size="0.02" rgba="1 0 0 1" />
          </body>
          <body name="right_thigh" pos="0 -0.0945763 0.161012">
            <joint name="right_hip_x" type="hinge" axis="1 0 0" pos="0 0 0" range="-40.0 20.0" damping="4.0" armature="0.01" frictionloss="0.3" />
            <joint name="right_hip_y" type="hinge" axis="0 1 0" pos="0 0 0" range="-40 50" damping="4.0" armature="0.01" frictionloss="0.3" />
            <joint name="right_hip_z" type="hinge" axis="0 0 1" pos="0 0 0" range="-30 100.0" damping="4.0" armature="0.01" frictionloss="0.3" />
            <geom type="capsule" size="0.08288135593220339 0.17822033898305084" pos="0 -0.21966101694915252 0" euler="-90 0 0" rgba="0.2 0.4 0.8 1.0" contype="0" conaffinity="0" />
            <inertial mass="9.225000000000001" pos="-0.018012203389830506 -0.18846915254237287 0.014497627118644068" fullinertia="0.1497367290043091 0.040060361505314564 0.16024144602125825 0.00872425650560184 -0.0007121842045389257 -0.00872425650560184" />
            <body name="right_shank" pos="0 -0.43932203389830504 0">
              <joint name="right_knee_z" type="hinge" axis="0 0 1" pos="0 0 0" range="-150 0.0" damping="5.0" armature="0.01" frictionloss="0.8" />
              <geom type="capsule" size="0.052372881355932197 0.19398305084745762" pos="0 -0.22016949152542373 0" euler="-90 0 0" rgba="0.2 0.4 0.8 1.0" contype="0" conaffinity="0" />
              <inertial mass="3.6" pos="-0.021136271186440677 -0.18053898305084745 0.0030823728813559317" fullinertia="0.054725890059178404 0.006980343119793164 0.054725890059178404 -0.001116854899166906 -0.0002792137247917265 0.001116854899166906" />
              <body name="right_foot" pos="0 -0.44033898305084745 0">
                <joint name="right_ankle_y" type="hinge" axis="0 1 0" pos="0 0 0" range="-30 30" damping="8.0" armature="0.01" frictionloss="1.0" />
                <joint name="right_ankle_z" type="hinge" axis="0 0 1" pos="0 0 0" range="-20 30.0" damping="8.0" armature="0.01" frictionloss="1.0" />
                <geom type="capsule" size="0.05135593220338983 0.04500000000000001" pos="0.07067796610169493 0 0" euler="0 90 0" rgba="0.2 0.4 0.8 1.0" solref="0.02 1" solimp="0.85 0.95 0.005" contype="0" conaffinity="0" condim="3" />
                <inertial mass="0.9" pos="0.0709606779661017 -0.028129830508474576 0.004806101694915256" fullinertia="0.000870394121229532 0.004317802241884517 0.004143363750646367 0.000519718803792014 -0.000217598530307383 0.0" />
                <site name="calcaneous_right" pos="-0.04677966101694915 -0.02135593220338983 0.00711864406779661" size="0.02" rgba="1 0 0 1" />
                <site name="first_metatarsal_head_right" pos="0.14847457627118643 -0.02135593220338983 -0.04779661016949152" size="0.02" rgba="1 0 0 1" />
                <site name="fifth_metatarsal_head_right" pos="0.13016949152542373 -0.02135593220338983 0.06101694915254237" size="0.02" rgba="1 0 0 1" />
                <site name="second_toe_tip_right" pos="0.22271186440677965 -0.009152542372881356 -0.001016949152542373" size="0.02" rgba="1 0 0 1" />
                <site name="centre_of_mass_foot_right" pos="0.04576271186440677 -0.03661016949152542 0.006101694915254237" size="0.02" rgba="1 0 0 1" />
                <site name="metatarsal_midpoint_right" pos="0.10576271186440676 0.0 0.0" size="0.02" rgba="1 0 0 1" />
                <geom name="right_foot_sole" type="box" pos="0.09 -0.045 0" size="0.145 0.012 0.075" rgba="0.1 0.1 0.1 0.35" friction="1.0 0.01 0.001" solref="0.02 1" solimp="0.85 0.95 0.005" contype="1" conaffinity="1" condim="3" />
              </body>
              <site name="tibiale_head_right" pos="0.02135593220338983 -0.027457627118644065 -0.04271186440677966" size="0.02" rgba="1 0 0 1" />
              <site name="fibula_head_right" pos="0.0 -0.023389830508474575 0.04779661016949152" size="0.02" rgba="1 0 0 1" />
              <site name="sphyrion_right" pos="0.02135593220338983 -0.4413559322033898 -0.0335593220338983" size="0.02" rgba="1 0 0 1" />
              <site name="lateral_malleolus_right" pos="-0.02135593220338983 -0.44033898305084745 0.0335593220338983" size="0.02" rgba="1 0 0 1" />
              <site name="centre_of_mass_shank_right" pos="-0.02135593220338983 -0.18101694915254235 0.0030508474576271187" size="0.02" rgba="1 0 0 1" />
            </body>
            <site name="greater_trochanter_right" pos="-0.04067796610169491 0.006101694915254237 0.10271186440677967" size="0.02" rgba="1 0 0 1" />
            <site name="lateral_femoral_epicondyle_right" pos="0.0 -0.4383050847457627 0.057966101694915256" size="0.02" rgba="1 0 0 1" />
            <site name="medial_femoral_epicondyle_right" pos="0.0 -0.43932203389830504 -0.057966101694915256" size="0.02" rgba="1 0 0 1" />
            <site name="centre_of_mass_thigh_right" pos="-0.01830508474576271 -0.18813559322033896 0.01423728813559322" size="0.02" rgba="1 0 0 1" />
          </body>
          <site name="midpoint_between_postero_superior_iliac_spines" pos="-0.10372881355932202 0.00711864406779661 0.0" size="0.02" rgba="1 0 0 1" />
          <site name="antero_superior_iliac_spine_right" pos="0.07932203389830508 0.00711864406779661 0.11389830508474576" size="0.02" rgba="1 0 0 1" />
          <site name="antero_superior_iliac_spine_left" pos="0.07932203389830508 0.00711864406779661 -0.11389830508474576" size="0.02" rgba="1 0 0 1" />
          <site name="symphision" pos="0.12508474576271186 -0.06813559322033898 0.0" size="0.02" rgba="1 0 0 1" />
          <site name="hip_joint_centre_right" pos="0.05694915254237288 -0.07627118644067796 0.0823728813559322" size="0.02" rgba="1 0 0 1" />
          <site name="hip_joint_centre_left" pos="0.05694915254237288 -0.07627118644067796 -0.0823728813559322" size="0.02" rgba="1 0 0 1" />
          <site name="centre_of_mass_pelvis" pos="-0.0030508474576271187 -0.02644067796610169 0.0" size="0.02" rgba="1 0 0 1" />
        </body>
        <site name="midspine_at_tenth_rib_level" pos="-0.05898305084745763 -0.025423728813559324 0.0" size="0.02" rgba="1 0 0 1" />
        <site name="tenth_rib_right" pos="0.0335593220338983 -0.031525423728813555 0.1494915254237288" size="0.02" rgba="1 0 0 1" />
        <site name="tenth_rib_left" pos="0.0335593220338983 -0.031525423728813555 -0.1494915254237288" size="0.02" rgba="1 0 0 1" />
        <site name="iliocristale_right" pos="0.020338983050847456 -0.08135593220338982 0.15966101694915252" size="0.02" rgba="1 0 0 1" />
        <site name="iliocristale_left" pos="0.020338983050847456 -0.08135593220338982 -0.15966101694915252" size="0.02" rgba="1 0 0 1" />
        <site name="anterior_superior_iliac_spine_right" pos="0.07016949152542373 -0.18203389830508473 0.11389830508474576" size="0.02" rgba="1 0 0 1" />
        <site name="anterior_superior_iliac_spine_left" pos="0.07016949152542373 -0.18203389830508473 -0.11389830508474576" size="0.02" rgba="1 0 0 1" />
        <site name="lumbar_joint_centre" pos="0.0 -0.1535593220338983 0.0" size="0.02" rgba="1 0 0 1" />
        <site name="centre_of_mass_abdomen" pos="0.02644067796610169 -0.05593220338983051 0.0" size="0.02" rgba="1 0 0 1" />
      </body>
      <body name="left_upper_arm" pos="0.019322033898305082 -0.08440677966101695 -0.20949152542372879">
        <joint name="left_shoulder_x" type="hinge" axis="1 0 0" pos="0 0 0" range="-50.0 180.0" damping="3.0" armature="0.006" frictionloss="0.8" stiffness="25.0" springref="0" />
        <joint name="left_shoulder_y" type="hinge" axis="0 1 0" pos="0 0 0" range="-90 90" damping="3.0" armature="0.006" frictionloss="0.8" stiffness="25.0" springref="0" />
        <joint name="left_shoulder_z" type="hinge" axis="0 0 1" pos="0 0 0" range="-50 180.0" damping="3.0" armature="0.006" frictionloss="0.8" stiffness="25.0" springref="0" />
        <geom type="capsule" size="0.05135593220338983 0.11516949152542373" pos="0 -0.11516949152542373 0" euler="-90 0 0" rgba="0.2 0.4 0.8 1.0" contype="0" conaffinity="0" />
        <inertial mass="1.8" pos="0.005070508474576272 -0.13577694915254238 0.008732542372881355" fullinertia="0.012012309586900315 0.0024138886090203965 0.012855028095374891 0.00035708411376041377 -0.0001285502809537489 0.0024138886090203965" />
        <body name="left_forearm" pos="0 -0.2816949152542373 0">
          <joint name="left_elbow_z" type="hinge" axis="0 0 1" pos="0 0 0" range="0 150.0" damping="2.0" armature="0.006" frictionloss="0.5" stiffness="12.0" springref="0" />
          <geom type="capsule" size="0.04372881355932203 0.12203389830508472" pos="0 -0.14389830508474574 0" euler="-90 0 0" rgba="0.2 0.4 0.8 1.0" contype="0" conaffinity="0" />
          <inertial mass="1.2750000000000001" pos="-0.0037413559322033896 -0.12001118644067796 -0.0031657627118644067" fullinertia="0.008279375806952026 0.001277811827348463 0.008279375806952026 0.0006758674128124101 1.0560428325193909e-05 -4.2241713300775634e-05" />
          <body name="left_hand" pos="0 -0.2877966101694915 0">
            <joint name="left_wrist_y" type="hinge" axis="0 1 0" pos="0 0 0" range="-80 80" damping="2.0" armature="0.003" frictionloss="0.3" stiffness="6.0" springref="0" />
            <joint name="left_wrist_z" type="hinge" axis="0 0 1" pos="0 0 0" range="-60 60.0" damping="2.0" armature="0.003" frictionloss="0.3" stiffness="6.0" springref="0" />
            <geom type="capsule" size="0.04525423728813559 0.01805084745762712" pos="0 -0.04067796610169491 0" euler="-90 0 0" rgba="0.2 0.4 0.8 1.0" contype="0" conaffinity="0" />
            <inertial mass="0.45" pos="0.0066711864406779646 -0.06825762711864407 -0.0061016949152542365" fullinertia="0.0011082829072105714 0.00043008882505027286 0.0009340433208848032 0.00014415719620798617 -6.701522550991094e-05 0.00011913817868428613" />
            <site name="secnd_metacarpal_head_left" pos="0.0 -0.08745762711864406 -0.04677966101694915" size="0.02" rgba="1 0 0 1" />
            <site name="fifth_metacarpal_head_left" pos="0.0 -0.07627118644067796 0.04677966101694915" size="0.02" rgba="1 0 0 1" />
            <site name="third_finger_tip_left" pos="0.00711864406779661 -0.19220338983050847 0.001016949152542373" size="0.02" rgba="1 0 0 1" />
            <site name="centre_of_mass_left" pos="0.00711864406779661 -0.06915254237288136 -0.006101694915254237" size="0.02" rgba="1 0 0 1" />
          </body>
          <site name="olecranion_left" pos="-0.008135593220338983 0.01423728813559322 0.0223728813559322" size="0.02" rgba="1 0 0 1" />
          <site name="ulnar_styloid_left" pos="0.0 -0.28881355932203384 0.0335593220338983" size="0.02" rgba="1 0 0 1" />
          <site name="radial_styloid_left" pos="0.0 -0.28881355932203384 -0.0335593220338983" size="0.02" rgba="1 0 0 1" />
          <site name="centre_of_mass_forearm_left" pos="0.0030508474576271187 -0.11999999999999998 -0.004067796610169492" size="0.02" rgba="1 0 0 1" />
        </body>
        <site name="lateral_humeral_epicondyle_left" pos="0.0 -0.2623728813559322 -0.04169491525423729" size="0.02" rgba="1 0 0 1" />
        <site name="medial_humeral_epicondyle_left" pos="0.0 -0.2684745762711864 0.04169491525423729" size="0.02" rgba="1 0 0 1" />
        <site name="centre_of_mass_upper_arm_left" pos="0.005084745762711864 -0.11999999999999998 -0.00711864406779661" size="0.02" rgba="1 0 0 1" />
      </body>
      <body name="right_upper_arm" pos="0.019322033898305082 -0.08440677966101695 0.20949152542372879">
        <joint name="right_shoulder_x" type="hinge" axis="1 0 0" pos="0 0 0" range="-180.0 50.0" damping="3.0" armature="0.006" frictionloss="0.8" stiffness="25.0" springref="0" />
        <joint name="right_shoulder_y" type="hinge" axis="0 1 0" pos="0 0 0" range="-90 90" damping="3.0" armature="0.006" frictionloss="0.8" stiffness="25.0" springref="0" />
        <joint name="right_shoulder_z" type="hinge" axis="0 0 1" pos="0 0 0" range="-50 180.0" damping="3.0" armature="0.006" frictionloss="0.8" stiffness="25.0" springref="0" />
        <geom type="capsule" size="0.05135593220338983 0.11516949152542373" pos="0 -0.11516949152542373 0" euler="-90 0 0" rgba="0.2 0.4 0.8 1.0" contype="0" conaffinity="0" />
        <inertial mass="1.8" pos="0.005070508474576272 -0.13577694915254238 -0.008732542372881355" fullinertia="0.012012309586900315 0.0024138886090203965 0.012855028095374891 0.00035708411376041377 0.0001285502809537489 -0.0024138886090203965" />
        <body name="right_forearm" pos="0 -0.2816949152542373 0">
          <joint name="right_elbow_z" type="hinge" axis="0 0 1" pos="0 0 0" range="0 150.0" damping="2.0" armature="0.006" frictionloss="0.5" stiffness="12.0" springref="0" />
          <geom type="capsule" size="0.04372881355932203 0.12203389830508472" pos="0 -0.14389830508474574 0" euler="-90 0 0" rgba="0.2 0.4 0.8 1.0" contype="0" conaffinity="0" />
          <inertial mass="1.2750000000000001" pos="-0.0037413559322033896 -0.12001118644067796 0.0031657627118644067" fullinertia="0.008279375806952026 0.001277811827348463 0.008279375806952026 0.0006758674128124101 -1.0560428325193909e-05 4.2241713300775634e-05" />
          <body name="right_hand" pos="0 -0.2877966101694915 0">
            <joint name="right_wrist_y" type="hinge" axis="0 1 0" pos="0 0 0" range="-80 80" damping="2.0" armature="0.003" frictionloss="0.3" stiffness="6.0" springref="0" />
            <joint name="right_wrist_z" type="hinge" axis="0 0 1" pos="0 0 0" range="-60 60.0" damping="2.0" armature="0.003" frictionloss="0.3" stiffness="6.0" springref="0" />
            <geom type="capsule" size="0.04525423728813559 0.01805084745762712" pos="0 -0.04067796610169491 0" euler="-90 0 0" rgba="0.2 0.4 0.8 1.0" contype="0" conaffinity="0" />
            <inertial mass="0.45" pos="0.0066711864406779646 -0.06825762711864407 0.0061016949152542365" fullinertia="0.0011082829072105714 0.00043008882505027286 0.0009340433208848032 0.00014415719620798617 6.701522550991094e-05 -0.00011913817868428613" />
            <site name="secnd_metacarpal_head_right" pos="0.0 -0.08745762711864406 0.04677966101694915" size="0.02" rgba="1 0 0 1" />
            <site name="fifth_metacarpal_head_right" pos="0.0 -0.07627118644067796 -0.04677966101694915" size="0.02" rgba="1 0 0 1" />
            <site name="third_finger_tip_right" pos="0.00711864406779661 -0.19220338983050847 -0.001016949152542373" size="0.02" rgba="1 0 0 1" />
            <site name="centre_of_mass_right" pos="0.00711864406779661 -0.06915254237288136 0.006101694915254237" size="0.02" rgba="1 0 0 1" />
          </body>
          <site name="olecranion_right" pos="-0.008135593220338983 0.01423728813559322 -0.0223728813559322" size="0.02" rgba="1 0 0 1" />
          <site name="ulnar_styloid_right" pos="0.0 -0.28881355932203384 -0.0335593220338983" size="0.02" rgba="1 0 0 1" />
          <site name="radial_styloid_right" pos="0.0 -0.28881355932203384 0.0335593220338983" size="0.02" rgba="1 0 0 1" />
          <site name="centre_of_mass_forearm_right" pos="0.0030508474576271187 -0.11999999999999998 0.004067796610169492" size="0.02" rgba="1 0 0 1" />
        </body>
        <site name="lateral_humeral_epicondyle_right" pos="0.0 -0.2623728813559322 0.04169491525423729" size="0.02" rgba="1 0 0 1" />
        <site name="medial_humeral_epicondyle_right" pos="0.0 -0.2684745762711864 -0.04169491525423729" size="0.02" rgba="1 0 0 1" />
        <site name="centre_of_mass_upper_arm_right" pos="0.005084745762711864 -0.11999999999999998 0.00711864406779661" size="0.02" rgba="1 0 0 1" />
      </body>
      <site name="seventh_cervicale" pos="-0.07322033898305084 0.02644067796610169 0.0" size="0.02" rgba="1 0 0 1" />
      <site name="suprasternale" pos="0.05186440677966101 -0.03966101694915254 0.0" size="0.02" rgba="1 0 0 1" />
      <site name="acromion_right" pos="-0.027457627118644065 -0.04576271186440677 0.20949152542372879" size="0.02" rgba="1 0 0 1" />
      <site name="acromion_left" pos="-0.027457627118644065 -0.04576271186440677 -0.20949152542372879" size="0.02" rgba="1 0 0 1" />
      <site name="shoulder_joint_centre_right" pos="0.019322033898305082 -0.08440677966101695 0.20949152542372879" size="0.02" rgba="1 0 0 1" />
      <site name="shoulder_joint_centre_left" pos="0.019322033898305082 -0.08440677966101695 -0.20949152542372879" size="0.02" rgba="1 0 0 1" />
      <site name="thoracic_joint_centre" pos="0.0 -0.33966101694915257 0.0" size="0.02" rgba="1 0 0 1" />
      <site name="centre_of_mass_thorax" pos="0.0 -0.18813559322033896 0.001016949152542373" size="0.02" rgba="1 0 0 1" />
    </body>
    <geom name="floor" type="plane" size="0 0 0.01" material="groundplane" friction="0.8" condim="3" contype="1" conaffinity="0" />
  </worldbody>
  <option gravity="0 0 -9.81" timestep="0.01" integrator="implicitfast" iterations="4" ls_iterations="5" />
  <keyframe>
    <key name="t-pose" qpos="0 0 1.5188135593220338 0.7071 0.7071 0 0 0 0 0 0 0 0 0 0 0 0 0 0 0 0 0 0 0 0 0 0 0 1.57079632679 0 0 0 0 0 -1.57079632679 0 0 0 0 0" ctrl="0 0 0 0 0 0 0 0 0 0 0 0" />
    <key name="a-pose" qpos="0 0 1.5188135593220338 0.7071 0.7071 0 0 0 0 0 0 0 0 0 0 0 0 0 0 0 0 0 0 0 0 0 0 0 0.75 0 0 0 0 0 -0.75 0 0 0 0 0" ctrl="0 0 0 0 0 0 0 0 0 0 0 0" />
  </keyframe>
  <statistic center="0 0 0.9" extent="2.2" />
  <asset>
    <texture type="2d" name="groundplane" builtin="checker" width="300" height="300" rgb1="1 1 1" rgb2=".85 .85 .85" />
    <material name="groundplane" texture="groundplane" texrepeat="6 6" texuniform="true" />
  </asset>
  <equality>
    <joint name="lock_abdomen_x" joint1="abdomen_x" polycoef="0 1 0 0 0" solref="0.002 1" solimp="0.999 0.9999 0.0001" />
    <joint name="lock_abdomen_y" joint1="abdomen_y" polycoef="0 1 0 0 0" solref="0.002 1" solimp="0.999 0.9999 0.0001" />
    <joint name="lock_abdomen_z" joint1="abdomen_z" polycoef="0 1 0 0 0" solref="0.002 1" solimp="0.999 0.9999 0.0001" />
    <joint name="lock_pelvis_x" joint1="pelvis_x" polycoef="0 1 0 0 0" solref="0.002 1" solimp="0.999 0.9999 0.0001" />
    <joint name="lock_pelvis_y" joint1="pelvis_y" polycoef="0 1 0 0 0" solref="0.002 1" solimp="0.999 0.9999 0.0001" />
    <joint name="lock_pelvis_z" joint1="pelvis_z" polycoef="0 1 0 0 0" solref="0.002 1" solimp="0.999 0.9999 0.0001" />
  </equality>
  <actuator>
    <position name="left_hip_x_position" joint="left_hip_x" kp="100" ctrllimited="true" ctrlrange="-0.349066 0.698132" forcelimited="true" forcerange="-180 180" />
    <position name="left_hip_y_position" joint="left_hip_y" kp="100" ctrllimited="true" ctrlrange="-0.698132 0.872665" forcelimited="true" forcerange="-180 180" />
    <position name="left_hip_z_position" joint="left_hip_z" kp="100" ctrllimited="true" ctrlrange="-0.523599 1.745329" forcelimited="true" forcerange="-180 180" />
    <position name="left_knee_z_position" joint="left_knee_z" kp="120" ctrllimited="true" ctrlrange="-2.617994 0.000000" forcelimited="true" forcerange="-180 180" />
    <position name="left_ankle_y_position" joint="left_ankle_y" kp="90" ctrllimited="true" ctrlrange="-0.523599 0.523599" forcelimited="true" forcerange="-160 160" />
    <position name="left_ankle_z_position" joint="left_ankle_z" kp="90" ctrllimited="true" ctrlrange="-0.349066 0.523599" forcelimited="true" forcerange="-160 160" />
    <position name="right_hip_x_position" joint="right_hip_x" kp="100" ctrllimited="true" ctrlrange="-0.698132 0.349066" forcelimited="true" forcerange="-180 180" />
    <position name="right_hip_y_position" joint="right_hip_y" kp="100" ctrllimited="true" ctrlrange="-0.698132 0.872665" forcelimited="true" forcerange="-180 180" />
    <position name="right_hip_z_position" joint="right_hip_z" kp="100" ctrllimited="true" ctrlrange="-0.523599 1.745329" forcelimited="true" forcerange="-180 180" />
    <position name="right_knee_z_position" joint="right_knee_z" kp="120" ctrllimited="true" ctrlrange="-2.617994 0.000000" forcelimited="true" forcerange="-180 180" />
    <position name="right_ankle_y_position" joint="right_ankle_y" kp="90" ctrllimited="true" ctrlrange="-0.523599 0.523599" forcelimited="true" forcerange="-160 160" />
    <position name="right_ankle_z_position" joint="right_ankle_z" kp="90" ctrllimited="true" ctrlrange="-0.349066 0.523599" forcelimited="true" forcerange="-160 160" />
  </actuator>
</mujoco>